<?xml version="1.0"?>
<robot name="myrobot">
<link name="incorporeal">
<inertial>
<origin xyz="0 0 0" rpy="0 0 0" />
<mass value ="0"/>
<inertia ixx="0" ixy="0" ixz="0" iyy="0" iyz="0" izz="0"/>
</inertial>
</link>
<link name="base">
<visual>
<origin xyz="0 0 0" rpy="0 0 0"/>
<geometry>
<box size="2 1.5 0.3"/>
</geometry>
<material name="cyan">
<color rgba="0 1 1 1"/>
</material>
</visual>
<inertial>
<origin xyz="0 0 0" rpy="0 0 0" />
<mass value ="10"/>
<inertia ixx="100" ixy="0" ixz="0" iyy="100" iyz="0" izz="100"/>
</inertial>
</link>
<link name="vertical_axis">
<visual>
<origin xyz="0 0 0" rpy="0 0 0" />
<geometry>
<box size="0.14 0.14 3"/>
</geometry>
<material name="blue">
<color rgba="0.2 0.3 0.4 1"/>
</material>
</visual>
<inertial>
<origin xyz="0 0 0" rpy="0 0 0"/>
<mass value ="5"/>
<inertia ixx="100" ixy="0" ixz="0" iyy="100" iyz="0" izz="100"/>
</inertial>
</link>
<link name="block">
<visual>
<origin xyz="0 0 0" rpy="0 0 0" />
<geometry>
<box size="1.3 0.4 0.33"/>
</geometry>
<material name="green">
<color rgba="0.1 0.6 0.1 1"/>
</material>
</visual>
<inertial>
<origin xyz="0 0 0" rpy="0 0 0"/>
<mass value ="2"/>
<inertia ixx="100" ixy="0" ixz="0" iyy="100" iyz="0" izz="100"/>
</inertial>
</link>
<link name="horizontal_axis">
<visual>
<origin xyz="0 0 0" rpy="1.5708 1.5708 0" />
<geometry>
<box size="0.11 0.11 2"/>
</geometry>
<material name="yellow">
<color rgba="1 0.99 0.82 1"/>
</material>
</visual>
<inertial>
<origin xyz="0 0 0" rpy="0 0 0"/>
<mass value ="2"/>
<inertia ixx="100" ixy="0" ixz="0" iyy="100" iyz="0" izz="100"/>
</inertial>
</link>
<link name="gripper">
<visual>
<origin xyz="2.15 0 0.35" rpy="0 0 0"/>
<geometry>
<mesh filename="package://myrobot_description/meshes/gripper.STL" scale = "0.005 0.005 0.005"/>
</geometry>
<material name="random">
<color rgba="0.6 0.5 0.5 1"/>
</material>
</visual>
<inertial>
<origin xyz="0 0 0" rpy="0 0 0"/>
<mass value ="1"/>
<inertia ixx="100" ixy="0" ixz="0" iyy="100" iyz="0" izz="100"/>
</inertial>
</link>
<joint name="immovable_connection" type="fixed">
<parent link="incorporeal"/>
<child link="base"/>
<origin xyz="0 0 0.15" rpy="0 0 0" />
<axis xyz="0 0 0"/>
<limit lower="0" upper="0" effort="0" velocity="0"/>
</joint>
<joint name="vertical_axis_movement" type="prismatic">
<parent link="base"/>
<child link="vertical_axis"/>
<origin xyz="0 0 1.5" rpy="0 0 0" />
<axis xyz="1 0 0"/>
<limit lower="-0.88" upper="0.88" effort="1000" velocity="0.5"/>
</joint>
<joint name="vertical_block_movement" type="prismatic">
<parent link="vertical_axis"/>
<child link="block"/>
<origin xyz="0.3 0 0.7" rpy="0 0 0" />
<axis xyz="0 0 1"/>
<limit lower="-1.635" upper="0.735" effort="1000" velocity="0.5"/>
</joint>
<joint name="horizontal_axis_movement" type="prismatic">
<parent link="block"/>
<child link="horizontal_axis"/>
<origin xyz="0.3 0.4 0" rpy="0 0 0" />
<axis xyz="0 1 0"/>
<limit lower="-0.7" upper="0.5" effort="1000" velocity="0.5"/>
</joint>
<joint name="gripper_connection" type="revolute<limit lower="0" upper="6.2832" effort="1000" velocity="0.5"/>">
<parent link="horizontal_axis"/>
<child link="gripper"/>
<origin xyz="-2.15 -0.4 0" rpy="1.5708 0 0" />
<axis xyz="0 1 0"/>
<limit lower="0" upper="" effort="0"  velocity="0"/>
</joint>
</robot>
